<?xml version="1.0" ?>
<!-- =================================================================================== -->
<!-- |    This document was autogenerated by xacro from hexapod.xacro                  | -->
<!-- |    EDITING THIS FILE BY HAND IS NOT RECOMMENDED                                 | -->
<!-- =================================================================================== -->
<robot name="hexapod">
  <!-- Base link -->
  <link name="base_link">
    <visual>
      <geometry>
        <box size="0.2 0.2 0.05"/>
      </geometry>
      <origin xyz="0 0 -0.025"/>
      <material name="grey">
        <color rgba="0.5 0.5 0.5 1"/>
      </material>
    </visual>
  </link>
  <!-- Coxa joint -->
  <joint name="coxa_joint_0" type="revolute">
    <parent link="base_link"/>
    <child link="coxa_0"/>
    <origin rpy="0 0 -2.35619" xyz="-0.09 -0.065 0"/>
    <axis xyz="0 0 1"/>
    <!-- Coxa rotates about the Z-axis -->
    <limit effort="10" lower="-1.39626" upper="1.39626" velocity="5"/>
  </joint>
  <link name="coxa_0">
    <visual>
      <geometry>
        <box size="0.05 0.02 0.02"/>
      </geometry>
      <material name="blue">
        <color rgba="0 0 1 1"/>
      </material>
    </visual>
  </link>
  <!-- Femur joint -->
  <joint name="femur_joint_0" type="revolute">
    <parent link="coxa_0"/>
    <child link="femur_0"/>
    <origin rpy="0 0 0" xyz="0.044 0 0"/>
    <axis xyz="0 1 0"/>
    <!-- Femur rotates about the Y-axis -->
    <limit effort="10" lower="-1.39626" upper="1.39626" velocity="5"/>
  </joint>
  <link name="femur_0">
    <visual>
      <geometry>
        <box size="0.08 0.02 0.02"/>
      </geometry>
      <material name="green">
        <color rgba="0 1 0 1"/>
      </material>
    </visual>
  </link>
  <!-- Tibia joint -->
  <joint name="tibia_joint_0" type="revolute">
    <parent link="femur_0"/>
    <child link="tibia_0"/>
    <origin rpy="0 0 0" xyz="0.08 0 0"/>
    <axis xyz="0 1 0"/>
    <!-- Tibia rotates about the Y-axis -->
    <limit effort="10" lower="-1.39626" upper="1.39626" velocity="5"/>
  </joint>
  <link name="tibia_0">
    <visual>
      <geometry>
        <box size="0.155 0.02 0.02"/>
      </geometry>
      <material name="red">
        <color rgba="1 0 0 1"/>
      </material>
    </visual>
  </link>
  <!-- Foot -->
  <joint name="foot_joint_0" type="fixed">
    <parent link="tibia_0"/>
    <child link="foot_0"/>
    <origin rpy="0 0 0" xyz="0 0 -0.155"/>
  </joint>
  <link name="foot_0">
    <visual>
      <geometry>
        <sphere radius="0.01"/>
      </geometry>
      <material name="black">
        <color rgba="0 0 0 1"/>
      </material>
    </visual>
  </link>
  <!-- Coxa joint -->
  <joint name="coxa_joint_1" type="revolute">
    <parent link="base_link"/>
    <child link="coxa_1"/>
    <origin rpy="0 0 -1.5708" xyz="0.0 -0.09 0"/>
    <axis xyz="0 0 1"/>
    <!-- Coxa rotates about the Z-axis -->
    <limit effort="10" lower="-1.39626" upper="1.39626" velocity="5"/>
  </joint>
  <link name="coxa_1">
    <visual>
      <geometry>
        <box size="0.05 0.02 0.02"/>
      </geometry>
      <material name="blue">
        <color rgba="0 0 1 1"/>
      </material>
    </visual>
  </link>
  <!-- Femur joint -->
  <joint name="femur_joint_1" type="revolute">
    <parent link="coxa_1"/>
    <child link="femur_1"/>
    <origin rpy="0 0 0" xyz="0.044 0 0"/>
    <axis xyz="0 1 0"/>
    <!-- Femur rotates about the Y-axis -->
    <limit effort="10" lower="-1.39626" upper="1.39626" velocity="5"/>
  </joint>
  <link name="femur_1">
    <visual>
      <geometry>
        <box size="0.08 0.02 0.02"/>
      </geometry>
      <material name="green">
        <color rgba="0 1 0 1"/>
      </material>
    </visual>
  </link>
  <!-- Tibia joint -->
  <joint name="tibia_joint_1" type="revolute">
    <parent link="femur_1"/>
    <child link="tibia_1"/>
    <origin rpy="0 0 0" xyz="0.08 0 0"/>
    <axis xyz="0 1 0"/>
    <!-- Tibia rotates about the Y-axis -->
    <limit effort="10" lower="-1.39626" upper="1.39626" velocity="5"/>
  </joint>
  <link name="tibia_1">
    <visual>
      <geometry>
        <box size="0.155 0.02 0.02"/>
      </geometry>
      <material name="red">
        <color rgba="1 0 0 1"/>
      </material>
    </visual>
  </link>
  <!-- Foot -->
  <joint name="foot_joint_1" type="fixed">
    <parent link="tibia_1"/>
    <child link="foot_1"/>
    <origin rpy="0 0 0" xyz="0 0 -0.155"/>
  </joint>
  <link name="foot_1">
    <visual>
      <geometry>
        <sphere radius="0.01"/>
      </geometry>
      <material name="black">
        <color rgba="0 0 0 1"/>
      </material>
    </visual>
  </link>
  <!-- Coxa joint -->
  <joint name="coxa_joint_2" type="revolute">
    <parent link="base_link"/>
    <child link="coxa_2"/>
    <origin rpy="0 0 -0.7854" xyz="0.09 -0.065 0"/>
    <axis xyz="0 0 1"/>
    <!-- Coxa rotates about the Z-axis -->
    <limit effort="10" lower="-1.39626" upper="1.39626" velocity="5"/>
  </joint>
  <link name="coxa_2">
    <visual>
      <geometry>
        <box size="0.05 0.02 0.02"/>
      </geometry>
      <material name="blue">
        <color rgba="0 0 1 1"/>
      </material>
    </visual>
  </link>
  <!-- Femur joint -->
  <joint name="femur_joint_2" type="revolute">
    <parent link="coxa_2"/>
    <child link="femur_2"/>
    <origin rpy="0 0 0" xyz="0.044 0 0"/>
    <axis xyz="0 1 0"/>
    <!-- Femur rotates about the Y-axis -->
    <limit effort="10" lower="-1.39626" upper="1.39626" velocity="5"/>
  </joint>
  <link name="femur_2">
    <visual>
      <geometry>
        <box size="0.08 0.02 0.02"/>
      </geometry>
      <material name="green">
        <color rgba="0 1 0 1"/>
      </material>
    </visual>
  </link>
  <!-- Tibia joint -->
  <joint name="tibia_joint_2" type="revolute">
    <parent link="femur_2"/>
    <child link="tibia_2"/>
    <origin rpy="0 0 0" xyz="0.08 0 0"/>
    <axis xyz="0 1 0"/>
    <!-- Tibia rotates about the Y-axis -->
    <limit effort="10" lower="-1.39626" upper="1.39626" velocity="5"/>
  </joint>
  <link name="tibia_2">
    <visual>
      <geometry>
        <box size="0.155 0.02 0.02"/>
      </geometry>
      <material name="red">
        <color rgba="1 0 0 1"/>
      </material>
    </visual>
  </link>
  <!-- Foot -->
  <joint name="foot_joint_2" type="fixed">
    <parent link="tibia_2"/>
    <child link="foot_2"/>
    <origin rpy="0 0 0" xyz="0 0 -0.155"/>
  </joint>
  <link name="foot_2">
    <visual>
      <geometry>
        <sphere radius="0.01"/>
      </geometry>
      <material name="black">
        <color rgba="0 0 0 1"/>
      </material>
    </visual>
  </link>
  <!-- Coxa joint -->
  <joint name="coxa_joint_3" type="revolute">
    <parent link="base_link"/>
    <child link="coxa_3"/>
    <origin rpy="0 0 2.35619" xyz="-0.09 0.065 0"/>
    <axis xyz="0 0 -1"/>
    <!-- Coxa rotates about the Z-axis -->
    <limit effort="10" lower="-1.39626" upper="1.39626" velocity="5"/>
  </joint>
  <link name="coxa_3">
    <visual>
      <geometry>
        <box size="0.05 0.02 0.02"/>
      </geometry>
      <material name="blue">
        <color rgba="0 0 1 1"/>
      </material>
    </visual>
  </link>
  <!-- Femur joint -->
  <joint name="femur_joint_3" type="revolute">
    <parent link="coxa_3"/>
    <child link="femur_3"/>
    <origin rpy="0 0 0" xyz="0.044 0 0"/>
    <axis xyz="0 -1 0"/>
    <!-- Femur rotates about the Y-axis -->
    <limit effort="10" lower="-1.39626" upper="1.39626" velocity="5"/>
  </joint>
  <link name="femur_3">
    <visual>
      <geometry>
        <box size="0.08 0.02 0.02"/>
      </geometry>
      <material name="green">
        <color rgba="0 1 0 1"/>
      </material>
    </visual>
  </link>
  <!-- Tibia joint -->
  <joint name="tibia_joint_3" type="revolute">
    <parent link="femur_3"/>
    <child link="tibia_3"/>
    <origin rpy="0 0 0" xyz="0.08 0 0"/>
    <axis xyz="0 -1 0"/>
    <!-- Tibia rotates about the Y-axis -->
    <limit effort="10" lower="-1.39626" upper="1.39626" velocity="5"/>
  </joint>
  <link name="tibia_3">
    <visual>
      <geometry>
        <box size="0.155 0.02 0.02"/>
      </geometry>
      <material name="red">
        <color rgba="1 0 0 1"/>
      </material>
    </visual>
  </link>
  <!-- Foot -->
  <joint name="foot_joint_3" type="fixed">
    <parent link="tibia_3"/>
    <child link="foot_3"/>
    <origin rpy="0 0 0" xyz="0 0 -0.155"/>
  </joint>
  <link name="foot_3">
    <visual>
      <geometry>
        <sphere radius="0.01"/>
      </geometry>
      <material name="black">
        <color rgba="0 0 0 1"/>
      </material>
    </visual>
  </link>
  <!-- Coxa joint -->
  <joint name="coxa_joint_4" type="revolute">
    <parent link="base_link"/>
    <child link="coxa_4"/>
    <origin rpy="0 0 1.5708" xyz="0.0 0.09 0"/>
    <axis xyz="0 0 -1"/>
    <!-- Coxa rotates about the Z-axis -->
    <limit effort="10" lower="-1.39626" upper="1.39626" velocity="5"/>
  </joint>
  <link name="coxa_4">
    <visual>
      <geometry>
        <box size="0.05 0.02 0.02"/>
      </geometry>
      <material name="blue">
        <color rgba="0 0 1 1"/>
      </material>
    </visual>
  </link>
  <!-- Femur joint -->
  <joint name="femur_joint_4" type="revolute">
    <parent link="coxa_4"/>
    <child link="femur_4"/>
    <origin rpy="0 0 0" xyz="0.044 0 0"/>
    <axis xyz="0 -1 0"/>
    <!-- Femur rotates about the Y-axis -->
    <limit effort="10" lower="-1.39626" upper="1.39626" velocity="5"/>
  </joint>
  <link name="femur_4">
    <visual>
      <geometry>
        <box size="0.08 0.02 0.02"/>
      </geometry>
      <material name="green">
        <color rgba="0 1 0 1"/>
      </material>
    </visual>
  </link>
  <!-- Tibia joint -->
  <joint name="tibia_joint_4" type="revolute">
    <parent link="femur_4"/>
    <child link="tibia_4"/>
    <origin rpy="0 0 0" xyz="0.08 0 0"/>
    <axis xyz="0 -1 0"/>
    <!-- Tibia rotates about the Y-axis -->
    <limit effort="10" lower="-1.39626" upper="1.39626" velocity="5"/>
  </joint>
  <link name="tibia_4">
    <visual>
      <geometry>
        <box size="0.155 0.02 0.02"/>
      </geometry>
      <material name="red">
        <color rgba="1 0 0 1"/>
      </material>
    </visual>
  </link>
  <!-- Foot -->
  <joint name="foot_joint_4" type="fixed">
    <parent link="tibia_4"/>
    <child link="foot_4"/>
    <origin rpy="0 0 0" xyz="0 0 -0.155"/>
  </joint>
  <link name="foot_4">
    <visual>
      <geometry>
        <sphere radius="0.01"/>
      </geometry>
      <material name="black">
        <color rgba="0 0 0 1"/>
      </material>
    </visual>
  </link>
  <!-- Coxa joint -->
  <joint name="coxa_joint_5" type="revolute">
    <parent link="base_link"/>
    <child link="coxa_5"/>
    <origin rpy="0 0 0.7854" xyz="0.09 0.065 0"/>
    <axis xyz="0 0 -1"/>
    <!-- Coxa rotates about the Z-axis -->
    <limit effort="10" lower="-1.39626" upper="1.39626" velocity="5"/>
  </joint>
  <link name="coxa_5">
    <visual>
      <geometry>
        <box size="0.05 0.02 0.02"/>
      </geometry>
      <material name="blue">
        <color rgba="0 0 1 1"/>
      </material>
    </visual>
  </link>
  <!-- Femur joint -->
  <joint name="femur_joint_5" type="revolute">
    <parent link="coxa_5"/>
    <child link="femur_5"/>
    <origin rpy="0 0 0" xyz="0.044 0 0"/>
    <axis xyz="0 -1 0"/>
    <!-- Femur rotates about the Y-axis -->
    <limit effort="10" lower="-1.39626" upper="1.39626" velocity="5"/>
  </joint>
  <link name="femur_5">
    <visual>
      <geometry>
        <box size="0.08 0.02 0.02"/>
      </geometry>
      <material name="green">
        <color rgba="0 1 0 1"/>
      </material>
    </visual>
  </link>
  <!-- Tibia joint -->
  <joint name="tibia_joint_5" type="revolute">
    <parent link="femur_5"/>
    <child link="tibia_5"/>
    <origin rpy="0 0 0" xyz="0.08 0 0"/>
    <axis xyz="0 -1 0"/>
    <!-- Tibia rotates about the Y-axis -->
    <limit effort="10" lower="-1.39626" upper="1.39626" velocity="5"/>
  </joint>
  <link name="tibia_5">
    <visual>
      <geometry>
        <box size="0.155 0.02 0.02"/>
      </geometry>
      <material name="red">
        <color rgba="1 0 0 1"/>
      </material>
    </visual>
  </link>
  <!-- Foot -->
  <joint name="foot_joint_5" type="fixed">
    <parent link="tibia_5"/>
    <child link="foot_5"/>
    <origin rpy="0 0 0" xyz="0 0 -0.155"/>
  </joint>
  <link name="foot_5">
    <visual>
      <geometry>
        <sphere radius="0.01"/>
      </geometry>
      <material name="black">
        <color rgba="0 0 0 1"/>
      </material>
    </visual>
  </link>
  <!-- Front Right -->
</robot>
